Workbook

Sheet 10X-03C
A2: To : AMEC: MAR Dept.,P/S Dept.,IS Dept.,PUS Dept. | G2: AMEC Design Schedule (10X'26-3C'27) | Y2: Rev. | Z2: Dated | AA2: Rev. | AB2: Dated
A3: From : DE Dept. | Y3: * | AA3: E
Y4: A | AA4: F
Y5: B | AA5: G
Y6: C | AA6: H
Y7: D | AA7: I
D9: 10XN | E9: 10XT | F9: 10AN | G9: 10AT | H9: 10YN | I9: 10YT | J9: 10BN | K9: 10BT | L9: 10ZN | M9: 10ZT | N9: 10CN | O9: 10CT | P9: 11XN | Q9: 11XT | R9: 11AN | S9: 11AT | T9: 11YN | U9: 11YT | V9: 11BN | W9: 11BT | X9: 11ZN | Y9: 11ZT | Z9: 11CN | AA9: 11CT | AB9: 12XN | AC9: 12XT | AD9: 12AN | AE9: 12AT | AF9: 12YN | AG9: 12YT | AH9: 12BN | AI9: 12BT | AJ9: 12ZN | AK9: 12ZT | AL9: 12CN | AM9: 12CT
A10: MAR issue Go-Design | D10: =Template!G2 -> 0 | E10: =Template!G3 -> 0 | F10: =Template!G4 -> 0 | G10: =Template!G5 -> 0 | H10: =Template!G6 -> 0 | I10: =Template!G7 -> 0 | J10: =Template!G8 -> 0 | K10: =Template!G9 -> 0 | L10: =Template!G10 -> 0 | M10: =Template!G11 -> 0 | N10: =Template!G12 -> 0 | O10: =Template!G13 -> 0 | P10: =Template!G14 -> 0 | Q10: =Template!G15 -> 0 | R10: =Template!G16 -> 0 | S10: =Template!G17 -> 0 | T10: =Template!G18 -> 0 | U10: =Template!G19 -> 0 | V10: =Template!G20 -> 0 | W10: =Template!G21 -> 0 | X10: =Template!G22 -> 0 | Y10: =Template!G23 -> 0 | Z10: =Template!G24 -> 0 | AA10: =Template!G25 -> 0 | AB10: =Template!G26 -> 0 | AC10: =Template!G27 -> 0 | AD10: =Template!G28 -> 0 | AE10: =Template!G29 -> 0 | AF10: =Template!G30 -> 0 | AG10: =Template!G31 -> 0 | AH10: =Template!G32 -> 0 | AI10: =Template!G33 -> 0 | AJ10: =Template!G34 -> 0 | AK10: =Template!G35 -> 0 | AL10: =Template!G36 -> 0 | AM10: =Template!G37 -> 0
A11: Confirm MELINA Portion | D11: =Template!I2 -> 0 | E11: =Template!I3 -> 0 | F11: =Template!I4 -> 0 | G11: =Template!I5 -> 0 | H11: =Template!I6 -> 0 | I11: =Template!I7 -> 0 | J11: =Template!I8 -> 0 | K11: =Template!I9 -> 0 | L11: =Template!I10 -> 0 | M11: =Template!I11 -> 0 | N11: =Template!I12 -> 0 | O11: =Template!I13 -> 0 | P11: =Template!I14 -> 0 | Q11: =Template!I15 -> 0 | R11: =Template!I16 -> 0 | S11: =Template!I17 -> 0 | T11: =Template!I18 -> 0 | U11: =Template!I19 -> 0 | V11: =Template!I20 -> 0 | W11: =Template!I21 -> 0 | X11: =Template!I22 -> 0 | Y11: =Template!I23 -> 0 | Z11: =Template!I24 -> 0 | AA11: =Template!I25 -> 0 | AB11: =Template!I26 -> 0 | AC11: =Template!I27 -> 0 | AD11: =Template!I28 -> 0 | AE11: =Template!I29 -> 0 | AF11: =Template!I30 -> 0 | AG11: =Template!I31 -> 0 | AH11: =Template!I32 -> 0 | AI11: =Template!I33 -> 0 | AJ11: =Template!I34 -> 0 | AK11: =Template!I35 -> 0 | AL11: =Template!I36 -> 0 | AM11: =Template!I37 -> 0
A12: MSE to MELINA (Pattern 2) | D12: =Template!$K2 -> 0 | E12: =Template!K3 -> 0 | F12: =Template!K4 -> 0 | G12: =Template!K5 -> 0 | H12: =Template!K6 -> 0 | I12: =Template!K7 -> 0 | J12: =Template!K8 -> 0 | K12: =Template!K9 -> 0 | L12: =Template!K10 -> 0 | M12: =Template!K11 -> 0 | N12: =Template!K12 -> 0 | O12: =Template!K13 -> 0 | P12: =Template!K14 -> 0 | Q12: =Template!K15 -> 0 | R12: =Template!K16 -> 0 | S12: =Template!K17 -> 0 | T12: =Template!K18 -> 0 | U12: =Template!K19 -> 0 | V12: =Template!K20 -> 0 | W12: =Template!K21 -> 0 | X12: =Template!K22 -> 0 | Y12: =Template!K23 -> 0 | Z12: =Template!K24 -> 0 | AA12: =Template!K25 -> 0 | AB12: =Template!K26 -> 0 | AC12: =Template!K27 -> 0 | AD12: =Template!K28 -> 0 | AE12: =Template!K29 -> 0 | AF12: =Template!K30 -> 0 | AG12: =Template!K31 -> 0 | AH12: =Template!K32 -> 0 | AI12: =Template!K33 -> 0 | AJ12: =Template!K34 -> 0 | AK12: =Template!K35 -> 0 | AL12: =Template!K$36 -> 0 | AM12: =Template!K$37 -> 0
A13: 0-Level Check/Check order | D13: =Template!O2 -> 0 | E13: =Template!O3 -> 0 | F13: =Template!O4 -> 0 | G13: =Template!O5 -> 0 | H13: =Template!O6 -> 0 | I13: =Template!O7 -> 0 | J13: =Template!O8 -> 0 | K13: =Template!O9 -> 0 | L13: =Template!O10 -> 0 | M13: =Template!O11 -> 0 | N13: =Template!O12 -> 0 | O13: =Template!O13 -> 0 | P13: =Template!O14 -> 0 | Q13: =Template!O15 -> 0 | R13: =Template!O16 -> 0 | S13: =Template!O17 -> 0 | T13: =Template!O18 -> 0 | U13: =Template!O19 -> 0 | V13: =Template!O20 -> 0 | W13: =Template!O21 -> 0 | X13: =Template!O22 -> 0 | Y13: =Template!O23 -> 0 | Z13: =Template!O24 -> 0 | AA13: =Template!O25 -> 0 | AB13: =Template!O26 -> 0 | AC13: =Template!O27 -> 0 | AD13: =Template!O28 -> 0 | AE13: =Template!O29 -> 0 | AF13: =Template!O30 -> 0 | AG13: =Template!O31 -> 0 | AH13: =Template!O32 -> 0 | AI13: =Template!O33 -> 0 | AJ13: =Template!O34 -> 0 | AK13: =Template!O35 -> 0 | AL13: =Template!O36 -> 0 | AM13: =Template!O37 -> 0
A14: Temp. Drawing | D14: =D13 -> 0 | E14: - | F14: =F13 -> 0 | G14: - | H14: =H13 -> 0 | I14: - | J14: =J13 -> 0 | K14: - | L14: =L13 -> 0 | M14: - | N14: =N13 -> 0 | O14: - | P14: =P13 -> 0 | Q14: - | R14: =R13 -> 0 | S14: - | T14: =T13 -> 0 | U14: - | V14: =V13 -> 0 | W14: - | X14: =X13 -> 0 | Y14: - | Z14: =Z13 -> 0 | AA14: - | AB14: =AB13 -> 0 | AC14: - | AD14: =AD13 -> 0 | AE14: - | AF14: =AF13 -> 0 | AG14: - | AH14: =AH13 -> 0 | AI14: - | AJ14: =AJ13 -> 0 | AK14: - | AL14: =AL13 -> 0 | AM14: -
A15: Design B/M Part list | D15: =Template!E2 -> 0 | E15: =Template!E3 -> 0 | F15: =Template!E4 -> 0 | G15: =Template!E5 -> 0 | H15: =Template!E6 -> 0 | I15: =Template!E7 -> 0 | J15: =Template!E8 -> 0 | K15: =Template!E9 -> 0 | L15: =Template!E10 -> 0 | M15: =Template!E11 -> 0 | N15: =Template!E12 -> 0 | O15: =Template!E13 -> 0 | P15: =Template!E14 -> 0 | Q15: =Template!E15 -> 0 | R15: =Template!E16 -> 0 | S15: =Template!E17 -> 0 | T15: =Template!E18 -> 0 | U15: =Template!E19 -> 0 | V15: =Template!E20 -> 0 | W15: =Template!E21 -> 0 | X15: =Template!E22 -> 0 | Y15: =Template!E23 -> 0 | Z15: =Template!E24 -> 0 | AA15: =Template!E25 -> 0 | AB15: =Template!E26 -> 0 | AC15: =Template!E27 -> 0 | AD15: =Template!E28 -> 0 | AE15: =Template!E29 -> 0 | AF15: =Template!E30 -> 0 | AG15: =Template!E31 -> 0 | AH15: =Template!E32 -> 0 | AI15: =Template!E33 -> 0 | AJ15: =Template!E34 -> 0 | AK15: =Template!E35 -> 0 | AL15: =Template!E36 -> 0 | AM15: =Template!E37 -> 0
A16: Day between DES B/M date | D16: =Template!$Q$2 -> 0 | E16: =Template!$Q$3 -> 0 | F16: =Template!$Q$4 -> 0 | G16: =Template!$Q$5 -> 0 | H16: =Template!$Q$6 -> 0 | I16: =Template!$Q$7 -> 0 | J16: =Template!$Q$8 -> 0 | K16: =Template!$Q$9 -> 0 | L16: =Template!$Q$10 -> 0 | M16: =Template!$Q$11 -> 0 | N16: =Template!$Q$12 -> 0 | O16: =Template!$Q$13 -> 0 | P16: =Template!$Q$14 -> 0 | Q16: =Template!$Q$15 -> 0 | R16: =Template!$Q$16 -> 0 | S16: =Template!$Q$17 -> 0 | T16: =Template!$Q$18 -> 0 | U16: =Template!$Q$19 -> 0 | V16: =Template!$Q$20 -> 0 | W16: =Template!$Q$21 -> 0 | X16: =Template!$Q$22 -> 0 | Y16: =Template!$Q$23 -> 0 | Z16: =Template!$Q$24 -> 0 | AA16: =Template!$Q$25 -> 0 | AB16: =Template!$Q$26 -> 0 | AC16: =Template!$Q$27 -> 0 | AD16: =Template!$Q$28 -> 0 | AE16: =Template!$Q$29 -> 0 | AF16: =Template!$Q$30 -> 0 | AG16: =Template!$Q$31 -> 0 | AH16: =Template!$Q$32 -> 0 | AI16: =Template!$Q$33 -> 0 | AJ16: =Template!$Q$34 -> 0 | AK16: =Template!$Q$35 -> 0 | AL16: =Template!$Q$36 -> 0 | AM16: =Template!$Q$37 -> 0
A17: MFG_B/M | D17: =Template!C2 -> 0 | E17: =Template!C3 -> 0 | F17: =Template!C4 -> 0 | G17: =Template!C5 -> 0 | H17: =Template!C6 -> 0 | I17: =Template!C7 -> 0 | J17: =Template!C8 -> 0 | K17: =Template!C9 -> 0 | L17: =Template!C10 -> 0 | M17: =Template!C11 -> 0 | N17: =Template!C12 -> 0 | O17: =Template!C13 -> 0 | P17: =Template!C14 -> 0 | Q17: =Template!C15 -> 0 | R17: =Template!C16 -> 0 | S17: =Template!C17 -> 0 | T17: =Template!C18 -> 0 | U17: =Template!C19 -> 0 | V17: =Template!C20 -> 0 | W17: =Template!C21 -> 0 | X17: =Template!C22 -> 0 | Y17: =Template!C23 -> 0 | Z17: =Template!C24 -> 0 | AA17: =Template!C25 -> 0 | AB17: =Template!C26 -> 0 | AC17: =Template!C27 -> 0 | AD17: =Template!C28 -> 0 | AE17: =Template!C29 -> 0 | AF17: =Template!C30 -> 0 | AG17: =Template!C31 -> 0 | AH17: =Template!C32 -> 0 | AI17: =Template!C33 -> 0 | AJ17: =Template!C34 -> 0 | AK17: =Template!C35 -> 0 | AL17: =Template!C36 -> 0 | AM17: =Template!C37 -> 0
A18: S/W Auto Assembly | D18: =Template!M2 -> 0 | E18: =Template!M3 -> 0 | F18: =Template!M4 -> 0 | G18: =Template!M5 -> 0 | H18: =Template!M6 -> 0 | I18: =Template!M7 -> 0 | J18: =Template!M8 -> 0 | K18: =Template!M9 -> 0 | L18: =Template!M10 -> 0 | M18: =Template!M11 -> 0 | N18: =Template!M12 -> 0 | O18: =Template!M13 -> 0 | P18: =Template!M14 -> 0 | Q18: =Template!M15 -> 0 | R18: =Template!M16 -> 0 | S18: =Template!M17 -> 0 | T18: =Template!M18 -> 0 | U18: =Template!M19 -> 0 | V18: =Template!M20 -> 0 | W18: =Template!M21 -> 0 | X18: =Template!M22 -> 0 | Y18: =Template!M23 -> 0 | Z18: =Template!M24 -> 0 | AA18: =Template!M25 -> 0 | AB18: =Template!M26 -> 0 | AC18: =Template!M27 -> 0 | AD18: =Template!M28 -> 0 | AE18: =Template!M29 -> 0 | AF18: =Template!M30 -> 0 | AG18: =Template!M31 -> 0 | AH18: =Template!M32 -> 0 | AI18: =Template!M33 -> 0 | AJ18: =Template!M34 -> 0 | AK18: =Template!M35 -> 0 | AL18: =Template!M36 -> 0 | AM18: =Template!M37 -> 0
D19: 01XN | E19: 01XT | F19: 01AN | G19: 01AT | H19: 01YN | I19: 01YT | J19: 01BN | K19: 01BT | L19: 01ZN | M19: 01ZT | N19: 01CN | O19: 01CT | P19: 02XN | Q19: 02XT | R19: 02AN | S19: 02AT | T19: 02YN | U19: 02YT | V19: 02BN | W19: 02BT | X19: 02ZN | Y19: 02ZT | Z19: 02CN | AA19: 02CT | AB19: 03XN | AC19: 03XT | AD19: 03AN | AE19: 03AT | AF19: 03YN | AG19: 03YT | AH19: 03BN | AI19: 03BT | AJ19: 03ZN | AK19: 03ZT | AL19: 03CN | AM19: 03CT
A20: MAR issue Go-Design | D20: =Template!G38 -> 0 | E20: =Template!G39 -> 0 | F20: =Template!G40 -> 0 | G20: =Template!G41 -> 0 | H20: =Template!G42 -> 0 | I20: =Template!G43 -> 0 | J20: =Template!G44 -> 0 | K20: =Template!G45 -> 0 | L20: =Template!G46 -> 0 | M20: =Template!G47 -> 0 | N20: =Template!G48 -> 0 | O20: =Template!G49 -> 0 | P20: =Template!G50 -> 0 | Q20: =Template!G51 -> 0 | R20: =Template!G52 -> 0 | S20: =Template!G53 -> 0 | T20: =Template!G54 -> 0 | U20: =Template!G55 -> 0 | V20: =Template!G56 -> 0 | W20: =Template!G57 -> 0 | X20: =Template!G58 -> 0 | Y20: =Template!G59 -> 0 | Z20: =Template!G60 -> 0 | AA20: =Template!G61 -> 0 | AB20: =Template!G62 -> 0 | AC20: =Template!G63 -> 0 | AD20: =Template!G64 -> 0 | AE20: =Template!G65 -> 0 | AF20: =Template!G66 -> 0 | AG20: =Template!G67 -> 0 | AH20: =Template!G68 -> 0 | AI20: =Template!G69 -> 0 | AJ20: =Template!G70 -> 0 | AK20: =Template!G71 -> 0 | AL20: =Template!G72 -> 0 | AM20: =Template!G73 -> 0
A21: Confirm MELINA Portion | D21: =Template!I38 -> 0 | E21: =Template!I39 -> 0 | F21: =Template!I40 -> 0 | G21: =Template!I41 -> 0 | H21: =Template!I42 -> 0 | I21: =Template!I43 -> 0 | J21: =Template!I44 -> 0 | K21: =Template!I45 -> 0 | L21: =Template!I46 -> 0 | M21: =Template!I47 -> 0 | N21: =Template!I48 -> 0 | O21: =Template!I49 -> 0 | P21: =Template!I50 -> 0 | Q21: =Template!I51 -> 0 | R21: =Template!I52 -> 0 | S21: =Template!I53 -> 0 | T21: =Template!I54 -> 0 | U21: =Template!I55 -> 0 | V21: =Template!I56 -> 0 | W21: =Template!I57 -> 0 | X21: =Template!I58 -> 0 | Y21: =Template!I59 -> 0 | Z21: =Template!I60 -> 0 | AA21: =Template!I61 -> 0 | AB21: =Template!I62 -> 0 | AC21: =Template!I63 -> 0 | AD21: =Template!I64 -> 0 | AE21: =Template!I65 -> 0 | AF21: =Template!I66 -> 0 | AG21: =Template!I67 -> 0 | AH21: =Template!I68 -> 0 | AI21: =Template!I69 -> 0 | AJ21: =Template!I70 -> 0 | AK21: =Template!I71 -> 0 | AL21: =Template!I72 -> 0 | AM21: =Template!I73 -> 0
A22: MSE to MELINA (Pattern 2) | D22: =Template!K38 -> 0 | E22: =Template!K39 -> 0 | F22: =Template!K40 -> 0 | G22: =Template!K41 -> 0 | H22: =Template!K42 -> 0 | I22: =Template!K43 -> 0 | J22: =Template!K44 -> 0 | K22: =Template!K45 -> 0 | L22: =Template!K46 -> 0 | M22: =Template!K47 -> 0 | N22: =Template!K48 -> 0 | O22: =Template!K49 -> 0 | P22: =Template!K50 -> 0 | Q22: =Template!K51 -> 0 | R22: =Template!K52 -> 0 | S22: =Template!K53 -> 0 | T22: =Template!K54 -> 0 | U22: =Template!K55 -> 0 | V22: =Template!K56 -> 0 | W22: =Template!K57 -> 0 | X22: =Template!K58 -> 0 | Y22: =Template!K59 -> 0 | Z22: =Template!K60 -> 0 | AA22: =Template!K61 -> 0 | AB22: =Template!K62 -> 0 | AC22: =Template!K63 -> 0 | AD22: =Template!K64 -> 0 | AE22: =Template!K65 -> 0 | AF22: =Template!K66 -> 0 | AG22: =Template!K67 -> 0 | AH22: =Template!K68 -> 0 | AI22: =Template!K69 -> 0 | AJ22: =Template!K70 -> 0 | AK22: =Template!K71 -> 0 | AL22: =Template!K72 -> 0 | AM22: =Template!K73 -> 0
A23: 0-Level Check/Check order | D23: =Template!O38 -> 0 | E23: =Template!O39 -> 0 | F23: =Template!O40 -> 0 | G23: =Template!O41 -> 0 | H23: =Template!O42 -> 0 | I23: =Template!O43 -> 0 | J23: =Template!O44 -> 0 | K23: =Template!O45 -> 0 | L23: =Template!O46 -> 0 | M23: =Template!O47 -> 0 | N23: =Template!O48 -> 0 | O23: =Template!O49 -> 0 | P23: =Template!O50 -> 0 | Q23: =Template!O51 -> 0 | R23: =Template!O52 -> 0 | S23: =Template!O53 -> 0 | T23: =Template!O54 -> 0 | U23: =Template!O55 -> 0 | V23: =Template!O56 -> 0 | W23: =Template!O57 -> 0 | X23: =Template!O58 -> 0 | Y23: =Template!O59 -> 0 | Z23: =Template!O60 -> 0 | AA23: =Template!O61 -> 0 | AB23: =Template!O62 -> 0 | AC23: =Template!O63 -> 0 | AD23: =Template!O64 -> 0 | AE23: =Template!O65 -> 0 | AF23: =Template!O66 -> 0 | AG23: =Template!O67 -> 0 | AH23: =Template!O68 -> 0 | AI23: =Template!O69 -> 0 | AJ23: =Template!O70 -> 0 | AK23: =Template!O71 -> 0 | AL23: =Template!O72 -> 0 | AM23: =Template!O73 -> 0
A24: Temp. Drawing | D24: =D23 -> 0 | E24: - | F24: =F23 -> 0 | G24: - | H24: =H23 -> 0 | I24: - | J24: =J23 -> 0 | K24: - | L24: =L23 -> 0 | M24: - | N24: =N23 -> 0 | O24: - | P24: =P23 -> 0 | Q24: - | R24: =R23 -> 0 | S24: - | T24: =T23 -> 0 | U24: - | V24: =V23 -> 0 | W24: - | X24: =X23 -> 0 | Y24: - | Z24: =Z23 -> 0 | AA24: - | AB24: =AB23 -> 0 | AC24: - | AD24: =AD23 -> 0 | AE24: - | AF24: =AF23 -> 0 | AG24: - | AH24: =AH23 -> 0 | AI24: - | AJ24: =AJ23 -> 0 | AK24: - | AL24: =AL23 -> 0 | AM24: -
A25: Design B/M Part list | D25: =Template!E38 -> 0 | E25: =Template!E39 -> 0 | F25: =Template!E40 -> 0 | G25: =Template!E41 -> 0 | H25: =Template!E42 -> 0 | I25: =Template!E43 -> 0 | J25: =Template!E44 -> 0 | K25: =Template!E45 -> 0 | L25: =Template!E46 -> 0 | M25: =Template!E47 -> 0 | N25: =Template!E48 -> 0 | O25: =Template!E49 -> 0 | P25: =Template!E50 -> 0 | Q25: =Template!E51 -> 0 | R25: =Template!E52 -> 0 | S25: =Template!E53 -> 0 | T25: =Template!E54 -> 0 | U25: =Template!E55 -> 0 | V25: =Template!E56 -> 0 | W25: =Template!E57 -> 0 | X25: =Template!E58 -> 0 | Y25: =Template!E59 -> 0 | Z25: =Template!E60 -> 0 | AA25: =Template!E61 -> 0 | AB25: =Template!E62 -> 0 | AC25: =Template!E63 -> 0 | AD25: =Template!E64 -> 0 | AE25: =Template!E65 -> 0 | AF25: =Template!E66 -> 0 | AG25: =Template!E67 -> 0 | AH25: =Template!E68 -> 0 | AI25: =Template!E69 -> 0 | AJ25: =Template!E70 -> 0 | AK25: =Template!E71 -> 0 | AL25: =Template!E72 -> 0 | AM25: =Template!E73 -> 0
A26: Day between DES B/M date | D26: =Template!$Q$38 -> 0 | E26: =Template!Q42 -> 0 | F26: =Template!$Q$40 -> 0 | G26: =Template!$Q$41 -> 0 | H26: =Template!$Q$42 -> 0 | I26: =Template!$Q$43 -> 0 | J26: =Template!$Q$44 -> 0 | K26: 4 | L26: =Template!$Q$46 -> 0 | M26: =Template!$Q$47 -> 0 | N26: =Template!$Q$48 -> 0 | O26: =Template!$Q$49 -> 0 | P26: =Template!$Q$50 -> 0 | Q26: =Template!$Q$51 -> 0 | R26: =Template!$Q$52 -> 0 | S26: =Template!$Q$53 -> 0 | T26: =Template!$Q$54 -> 0 | U26: =Template!$Q$55 -> 0 | V26: =Template!$Q$56 -> 0 | W26: =Template!$Q$57 -> 0 | X26: =Template!$Q$58 -> 0 | Y26: =Template!$Q$59 -> 0 | Z26: =Template!$Q$60 -> 0 | AA26: =Template!$Q$61 -> 0 | AB26: =Template!$Q$62 -> 0 | AC26: =Template!$Q$63 -> 0 | AD26: =Template!$Q$64 -> 0 | AE26: =Template!$Q$65 -> 0 | AF26: =Template!$Q$66 -> 0 | AG26: =Template!$Q$67 -> 0 | AH26: =Template!$Q$68 -> 0 | AI26: =Template!$Q$69 -> 0 | AJ26: =Template!$Q$70 -> 0 | AK26: =Template!$Q$71 -> 0 | AL26: =Template!$Q$72 -> 0 | AM26: =Template!$Q$73 -> 0
A27: MFG_B/M | D27: =Template!C38 -> 0 | E27: =Template!C39 -> 0 | F27: =Template!C40 -> 0 | G27: =Template!C41 -> 0 | H27: =Template!C42 -> 0 | I27: =Template!C43 -> 0 | J27: =Template!C44 -> 0 | K27: =Template!C45 -> 0 | L27: =Template!C46 -> 0 | M27: =Template!C47 -> 0 | N27: =Template!C48 -> 0 | O27: =Template!C49 -> 0 | P27: =Template!C50 -> 0 | Q27: =Template!C51 -> 0 | R27: =Template!C52 -> 0 | S27: =Template!C53 -> 0 | T27: =Template!C54 -> 0 | U27: =Template!C55 -> 0 | V27: =Template!C56 -> 0 | W27: =Template!C57 -> 0 | X27: =Template!C58 -> 0 | Y27: =Template!C59 -> 0 | Z27: =Template!C60 -> 0 | AA27: =Template!C61 -> 0 | AB27: =Template!C62 -> 0 | AC27: =Template!C63 -> 0 | AD27: =Template!C64 -> 0 | AE27: =Template!C65 -> 0 | AF27: =Template!C66 -> 0 | AG27: =Template!C67 -> 0 | AH27: =Template!C68 -> 0 | AI27: =Template!C69 -> 0 | AJ27: =Template!C70 -> 0 | AK27: =Template!C71 -> 0 | AL27: =Template!C72 -> 0 | AM27: =Template!C73 -> 0
A28: S/W Auto Assembly | D28: =Template!M38 -> 0 | E28: =Template!M39 -> 0 | F28: =Template!M40 -> 0 | G28: =Template!M41 -> 0 | H28: =Template!M42 -> 0 | I28: =Template!M43 -> 0 | J28: =Template!M44 -> 0 | K28: =Template!M45 -> 0 | L28: =Template!M46 -> 0 | M28: =Template!M47 -> 0 | N28: =Template!M48 -> 0 | O28: =Template!M49 -> 0 | P28: =Template!M50 -> 0 | Q28: =Template!M51 -> 0 | R28: =Template!M52 -> 0 | S28: =Template!M53 -> 0 | T28: =Template!M54 -> 0 | U28: =Template!M55 -> 0 | V28: =Template!M56 -> 0 | W28: =Template!M57 -> 0 | X28: =Template!M58 -> 0 | Y28: =Template!M59 -> 0 | Z28: =Template!M60 -> 0 | AA28: =Template!M61 -> 0 | AB28: =Template!M62 -> 0 | AC28: =Template!M63 -> 0 | AD28: =Template!M64 -> 0 | AE28: =Template!M65 -> 0 | AF28: =Template!M66 -> 0 | AG28: =Template!M67 -> 0 | AH28: =Template!M68 -> 0 | AI28: =Template!M69 -> 0 | AJ28: =Template!M70 -> 0 | AK28: =Template!M71 -> 0 | AL28: =Template!M72 -> 0 | AM28: =Template!M73 -> 0
A31: GO-DESIGN | R31: AMEC Production Lead-time (30,60&90 days) after specification finalize.
A32: 10XN | B32: =Template!G2 -> 0 | C32: 11XN | D32: =Template!G14 -> 0 | E32: 12XN | F32: =Template!G26 -> 0 | G32: 01XN | H32: =Template!G38 -> 0 | I32: 02XN | J32: =Template!G50 -> 0 | K32: 03XN | L32: =Template!G62 -> 0
A33: 10XT | B33: =Template!G3 -> 0 | C33: 11XT | D33: =Template!G15 -> 0 | E33: 12XT | F33: =Template!G27 -> 0 | G33: 01XT | H33: =Template!G39 -> 0 | I33: 02XT | J33: =Template!G51 -> 0 | K33: 03XT | L33: =Template!G63 -> 0 | R33: L/T = 30 days | T33: MAR(1) | U33: DES(1) | V33: P/P(3) | W33: MFG(16) | AA33: P/C(3) | AB33: Shipment(6)
A34: 10AN | B34: =Template!G4 -> 0 | C34: 11AN | D34: =Template!G16 -> 0 | E34: 12AN | F34: =Template!G28 -> 0 | G34: 01AN | H34: =Template!G40 -> 0 | I34: 02AN | J34: =Template!G52 -> 0 | K34: 03AN | L34: =Template!G64 -> 0
A35: 10AT | B35: =Template!G5 -> 0 | C35: 11AT | D35: =Template!G17 -> 0 | E35: 12AT | F35: =Template!G29 -> 0 | G35: 01AT | H35: =Template!G41 -> 0 | I35: 02AT | J35: =Template!G53 -> 0 | K35: 03AT | L35: =Template!G65 -> 0 | R35: L/T = 60 days | T35: MAR(5) | U35: DES(15) +JOP | W35: P/P(5) | X35: MFG(20) | AB35: P/C(5) | AC35: Shipment(10)
A36: 10YN | B36: =Template!G6 -> 0 | C36: 11YN | D36: =Template!G18 -> 0 | E36: 12YN | F36: =Template!G30 -> 0 | G36: 01YN | H36: =Template!G42 -> 0 | I36: 02YN | J36: =Template!G54 -> 0 | K36: 03YN | L36: =Template!G66 -> 0
A37: 10YT | B37: =Template!G7 -> 0 | C37: 11YT | D37: =Template!G19 -> 0 | E37: 12YT | F37: =Template!G31 -> 0 | G37: 01YT | H37: =Template!G43 -> 0 | I37: 02YT | J37: =Template!G55 -> 0 | K37: 03YT | L37: =Template!G67 -> 0 | R37: L/T = 90 days | T37: MAR(5) | U37: DES(15) | W37: JOP(30) | AA37: P/P(5) | AB37: MFG(20) | AF37: P/C(5) | AG37: Shipment(10)
A38: 10BN | B38: =Template!G8 -> 0 | C38: 11BN | D38: =Template!G20 -> 0 | E38: 12BN | F38: =Template!G32 -> 0 | G38: 01BN | H38: =Template!G44 -> 0 | I38: 02BN | J38: =Template!G56 -> 0 | K38: 03BN | L38: =Template!G68 -> 0
A39: 10BT | B39: =Template!G9 -> 0 | C39: 11BT | D39: =Template!G21 -> 0 | E39: 12BT | F39: =Template!G33 -> 0 | G39: 01BT | H39: =Template!G45 -> 0 | I39: 02BT | J39: =Template!G57 -> 0 | K39: 03BT | L39: =Template!G69 -> 0 | R39: Note: (X) = days, The value in parenthese is the number of days.
A40: 10ZN | B40: =Template!G10 -> 0 | C40: 11ZN | D40: =Template!G22 -> 0 | E40: 12ZN | F40: =Template!G34 -> 0 | G40: 01ZN | H40: =Template!G46 -> 0 | I40: 02ZN | J40: =Template!G58 -> 0 | K40: 03ZN | L40: =Template!G70 -> 0 | R40: Condition of Design Class for set-up Production schedule
A41: 10ZT | B41: =Template!G11 -> 0 | C41: 11ZT | D41: =Template!G23 -> 0 | E41: 12ZT | F41: =Template!G35 -> 0 | G41: 01ZT | H41: =Template!G47 -> 0 | I41: 02ZT | J41: =Template!G59 -> 0 | K41: 03ZT | L41: =Template!G71 -> 0
A42: 10CN | B42: =Template!G12 -> 0 | C42: 11CN | D42: =Template!G24 -> 0 | E42: 12CN | F42: =Template!G36 -> 0 | G42: 01CN | H42: =Template!G48 -> 0 | I42: 02CN | J42: =Template!G60 -> 0 | K42: 03CN | L42: =Template!G72 -> 0 | R42: DES_class | S42: DES_time | T42: Condition | W42: DES_jun | X42: JOP | Y42: L/T of JOP | AA42: Production L/T | AC42: Remark
A43: 10CT | B43: =Template!G13 -> 0 | C43: 11CT | D43: =Template!G25 -> 0 | E43: 12CT | F43: =Template!G37 -> 0 | G43: 01CT | H43: =Template!G49 -> 0 | I43: 02CT | J43: =Template!G61 -> 0 | K43: 03CT | L43: =Template!G73 -> 0 | R43: A | S43: 0 | T43: Alpha package, DBP | W43: T | X43: Without | Y43: - | AA43: 30 days | AC43: Alpha package, DBP, No JOP
R44: B- E (*2) | S44: 15 | T44: STD & Special specs | W44: N | X44: Without | Y44: - | AA44: 60 days | AC44: Non-Alpha, No-JOP
...

Sheet Template
A1: No. | B1: PROD | C1: MFG BM | D1: P | E1: DES BM | F1: TIME DES BM TO MFG BM | G1: Go-DES | H1: Time Go-des to DES BM date | I1: Confirm MELINA Portion | J1: TIME | K1: MSE to MELINA (Pattern 2) | L1: TIME | M1: SW.Assembly | N1: Time | O1: 0-Level check and Temp DWG. | P1: Time | Q1: Design working day | R1: L/T | S1: TIME DES BM TO MFG BM
A2: 1 | B2: 202610XN
A3: 2 | B3: 202610XT
A4: 3 | B4: 202610AN
A5: 4 | B5: 202610AT
A6: 5 | B6: 202610YN
A7: 6 | B7: 202610YT
A8: 7 | B8: 202610BN
A9: 8 | B9: 202610BT
A10: 9 | B10: 202610ZN
A11: 10 | B11: 202610ZT
A12: 11 | B12: 202610CN
A13: 12 | B13: 202610CT
... A73: 72 | B73: 202703CT

Sheet ความหมายของสูตร
A2: +1”Add order” + (F17"MFG BM Last P" - F10"Issued GO DES")+20”MFG”+15(QC5+VAN10)
A4: 1 | B4: + | C4: F17 | D4: - | E4: F10 | F4: + | G4: 20 | H4: + | I4: 15
A5: (Add order) | C5: (MFG BM Last P) | E5: Issued GO DES | G5: MFG | I5: (QC5+VAN10)

Sheet LT40Days
A1: DES BM for support reduce lead time 40 days.
A3: Concept
B4: 1 | C4: 2 | D4: 3 | E4: 4 | F4: Working only
B5: MAR Add order | C5: MAP Setup | D5: DES B/M | E5: PP B/M
F7: Condition
F8: Go Design | G8: Same with JUN "N"
F12: 0-level | G12: Design B/M - 1 (Only working day)
F14: Design B/M | G14: MFG B/M-1 (Only working day)
F16: MFG B/M | G16: Refer AMEC MFG B/M schedule P3 or P4.
F18: S/W Auto Assembly | G18: Same with JUN "N"
A20: Production lead time 30 days.

Sheet Sheet2
